```
# refill_container.py

import sqlite3

from main import path

# connect to the database
conn = sqlite3.connect(path)
c = conn.cursor()

# select all the rows from the table
c.execute("SELECT * FROM medic")
rows = c.fetchall()

# loop through each row to check if drug_container needs to be refilled
for row in rows:
    pills_per_pack = 0  # initialize pills_per_pack to zero
    if int(row[5]) == 0:  # check if drug_container is empty
        if row[1] == "Losartana":
            pills_per_pack = 15
        elif row[1] == "AAS":
            pills_per_pack = 120
        elif row[1] == "Anlodipino":
            pills_per_pack = 15
        elif row[1] == "Hidroclorotiazida":
            pills_per_pack = 30
        elif row[1] == "Atorvastatina":
            pills_per_pack = 10

        packs_needed = (
            row[2] // pills_per_pack
        )  # calculate the number of packs needed to refill drug_container
        if packs_needed > 0:
            c.execute(
                "UPDATE medic SET drug_container=?, stock_medicine_box=? WHERE id=?",  # noqa: E501
                (
                    packs_needed * pills_per_pack,
                    row[2] - packs_needed * pills_per_pack,
                    row[0],
                ),
            )

            # check if stock_medicine_box is now zero and print an alert if it is # noqa: E501
            if row[2] - packs_needed * pills_per_pack == 0:
                print(
                    "ALERT: Stock for {} has run out. Please refill the stock.".format(  # noqa: E501
                        row[1]
                    )
                )

conn.commit()
conn.close()


```


There is a msg below:

Traceback (most recent call last):
  File "c:\Users\clldu\OneDrive\vsc_envir\first_project\project\src\utils\refill_container.py", line 32, in <module>
    c.execute(
sqlite3.OperationalError: no such column: id